Workbook

Sheet CUOTAS
A1: NOMBRE | B1: RUT | C1: Cuota Sindical | D1: Cuota Fenama | E1: Cuota Confederacion | F1: Descuento Dental | G1: Descuento Telefono/ Plan Celular | H1: Multa Sindical | I1: Otros_dctos SindIcal | J1: Oservacion | K1: SINDICATO | L1: SINDICATO SISTEMA(CORRECTO) | M1: TRUE | N1: EMPRESA
A2: NANCY MADARIAGA | B2: 11971775-2 | C2: 5000 | J2: DOBLE CUOTA | K2: SITAL | L2: =VLOOKUP(B2,'[1]Hoja 1'!$A:$J,10,0) -> #REF! | M2: =L2=K2 -> #REF! | N2: =VLOOKUP(B2,'[1]Hoja 1'!$A:$F,6,0) -> #REF!
A3: GLADYS POBLETE | B3: 18122103-8 | C3: 5000 | J3: DOBLE CUOTA | K3: SITAL | L3: =VLOOKUP(B3,'[1]Hoja 1'!$A:$J,10,0) -> #REF! | M3: =L3=K3 -> #REF! | N3: =VLOOKUP(B3,'[1]Hoja 1'!$A:$F,6,0) -> #REF!
A4: GIOCONDA RETAMALES | B4: 12406831-2 | C4: 5000 | J4: DOBLE CUOTA | K4: SITAL | L4: =VLOOKUP(B4,'[1]Hoja 1'!$A:$J,10,0) -> #REF! | M4: =L4=K4 -> #REF! | N4: =VLOOKUP(B4,'[1]Hoja 1'!$A:$F,6,0) -> #REF!
A5: EDITH BORDILLO | B5: 13031543-7 | C5: 5000 | J5: DOBLE CUOTA | K5: SITAL | L5: =VLOOKUP(B5,'[1]Hoja 1'!$A:$J,10,0) -> #REF! | M5: =L5=K5 -> #REF! | N5: =VLOOKUP(B5,'[1]Hoja 1'!$A:$F,6,0) -> #REF!
A6: AURORA ELOISA CARRASCO ALARCON | B6: 11293958-K | C6: 5000 | J6: DOBLE CUOTA | K6: SITAL | L6: =VLOOKUP(B6,'[1]Hoja 1'!$A:$J,10,0) -> #REF! | M6: =L6=K6 -> #REF! | N6: =VLOOKUP(B6,'[1]Hoja 1'!$A:$F,6,0) -> #REF!
A7: CAROLINA ALEXANDRA VASQUEZ GOMEZ | B7: 20139231-4 | C7: 5000 | J7: DOBLE CUOTA | K7: SITAL | L7: =VLOOKUP(B7,'[1]Hoja 1'!$A:$J,10,0) -> #REF! | M7: =L7=K7 -> #REF! | N7: =VLOOKUP(B7,'[1]Hoja 1'!$A:$F,6,0) -> #REF!
A8: CORINA DEL CARMEN GONZALEZ MUÑOZ | B8: 9479341-6 | C8: 5000 | J8: DOBLE CUOTA | K8: SITAL | L8: =VLOOKUP(B8,'[1]Hoja 1'!$A:$J,10,0) -> #REF! | M8: =L8=K8 -> #REF! | N8: =VLOOKUP(B8,'[1]Hoja 1'!$A:$F,6,0) -> #REF!
A9: ELSA CLARA BERGUÑO SANTIBAÑEZ | B9: 8603844-7 | C9: 5000 | J9: DOBLE CUOTA | K9: SITAL | L9: =VLOOKUP(B9,'[1]Hoja 1'!$A:$J,10,0) -> #REF! | M9: =L9=K9 -> #REF! | N9: =VLOOKUP(B9,'[1]Hoja 1'!$A:$F,6,0) -> #REF!
A10: JESSICA SOLANGE VARGAS BELLO | B10: 12906922-8 | C10: 5000 | J10: DOBLE CUOTA | K10: SITAL | L10: =VLOOKUP(B10,'[1]Hoja 1'!$A:$J,10,0) -> #REF! | M10: =L10=K10 -> #REF! | N10: =VLOOKUP(B10,'[1]Hoja 1'!$A:$F,6,0) -> #REF!
A11: KATHERINE BEATRIZ CARMONA GONZALEZ | B11: 16932964-8 | C11: 5000 | J11: DOBLE CUOTA | K11: SITAL | L11: =VLOOKUP(B11,'[1]Hoja 1'!$A:$J,10,0) -> #REF! | M11: =L11=K11 -> #REF! | N11: =VLOOKUP(B11,'[1]Hoja 1'!$A:$F,6,0) -> #REF!
A12: KATHERIN YSABEL GOMEZ NUÑEZ | B12: 15587846-0 | C12: 5000 | J12: DOBLE CUOTA | K12: SITAL | L12: =VLOOKUP(B12,'[1]Hoja 1'!$A:$J,10,0) -> #REF! | M12: =L12=K12 -> #REF! | N12: =VLOOKUP(B12,'[1]Hoja 1'!$A:$F,6,0) -> #REF!
A13: LUZ JIMENA TRAGO ANTIMAN | B13: 11796214-8 | C13: 5000 | J13: DOBLE CUOTA | K13: SITAL | L13: =VLOOKUP(B13,'[1]Hoja 1'!$A:$J,10,0) -> #REF! | M13: =L13=K13 -> #REF! | N13: =VLOOKUP(B13,'[1]Hoja 1'!$A:$F,6,0) -> #REF!
... A16: SUSSY MAGALY TAPIA PEREZ | B16: 12397855-2 | C16: 5000 | J16: DOBLE CUOTA | K16: SITAL | L16: =VLOOKUP(B16,'[1]Hoja 1'!$A:$J,10,0) -> #REF! | M16: =L16=K16 -> #REF! | N16: =VLOOKUP(B16,'[1]Hoja 1'!$A:$F,6,0) -> #REF!
A17: FANNY DEL CARMEN RAMUREZ JARA | B17: 12875395-8 | C17: 6000 | K17: SINDICATO INTEREMPRESA DE MANIPULADORAS DE ALIMENTOS DE LA PROVINCIA CORDILLERA | L17: =VLOOKUP(B17,'[1]Hoja 1'!$A:$J,10,0) -> #REF! | M17: =L17=K17 -> #REF! | N17: =VLOOKUP(B17,'[1]Hoja 1'!$A:$F,6,0) -> #REF!
A18: LYNDA RAQUEL ARAGON VALDES | B18: 13835916-6 | C18: 6000 | K18: SINDICATO INTEREMPRESA DE MANIPULADORAS DE ALIMENTOS DE LA PROVINCIA CORDILLERA | L18: =VLOOKUP(B18,'[1]Hoja 1'!$A:$J,10,0) -> #REF! | M18: =L18=K18 -> #REF! | N18: =VLOOKUP(B18,'[1]Hoja 1'!$A:$F,6,0) -> #REF!
A19: María Jacqueline Bazan Orellana | B19: 10459663-0 | C19: 5000 | I19: 2000 | K19: SINDICATO INTEREMPRESA SINTRAPAE RENQUI | L19: =VLOOKUP(B19,'[1]Hoja 1'!$A:$J,10,0) -> #REF! | M19: =L19=K19 -> #REF! | N19: =VLOOKUP(B19,'[1]Hoja 1'!$A:$F,6,0) -> #REF!
A20: Elena Margarita Ayala Cabrera | B20: 11549620-4 | C20: 5000 | I20: 2000 | K20: SINDICATO INTEREMPRESA SINTRAPAE RENQUI | L20: =VLOOKUP(B20,'[1]Hoja 1'!$A:$J,10,0) -> #REF! | M20: =L20=K20 -> #REF! | N20: =VLOOKUP(B20,'[1]Hoja 1'!$A:$F,6,0) -> #REF!
A21: Elsa Marisol Llanca Saavedra | B21: 10471922-8 | C21: 5000 | I21: 2000 | K21: SINDICATO INTEREMPRESA SINTRAPAE RENQUI | L21: =VLOOKUP(B21,'[1]Hoja 1'!$A:$J,10,0) -> #REF! | M21: =L21=K21 -> #REF! | N21: =VLOOKUP(B21,'[1]Hoja 1'!$A:$F,6,0) -> #REF!
A22: Yocelyn del Carmen Zapata Yáñez | B22: 15481206-7 | C22: 5000 | I22: 2000 | K22: SINDICATO INTEREMPRESA SINTRAPAE RENQUI | L22: =VLOOKUP(B22,'[1]Hoja 1'!$A:$J,10,0) -> #REF! | M22: =L22=K22 -> #REF! | N22: =VLOOKUP(B22,'[1]Hoja 1'!$A:$F,6,0) -> #REF!
A23: Laura del Carmen Molina Delgado | B23: 10074715-4 | C23: 5000 | I23: 2000 | K23: SINDICATO INTEREMPRESA SINTRAPAE RENQUI | L23: =VLOOKUP(B23,'[1]Hoja 1'!$A:$J,10,0) -> #REF! | M23: =L23=K23 -> #REF! | N23: =VLOOKUP(B23,'[1]Hoja 1'!$A:$F,6,0) -> #REF!
A24: Elizabeth Johana Aburto Silva | B24: 15505258-9 | C24: 5000 | I24: 2000 | K24: SINDICATO INTEREMPRESA SINTRAPAE RENQUI | L24: =VLOOKUP(B24,'[1]Hoja 1'!$A:$J,10,0) -> #REF! | M24: =L24=K24 -> #REF! | N24: =VLOOKUP(B24,'[1]Hoja 1'!$A:$F,6,0) -> #REF!
A25: Mariana Daniela Toledo jaque | B25: 17425935-6 | C25: 5000 | I25: 2000 | K25: SINDICATO INTEREMPRESA SINTRAPAE RENQUI | L25: =VLOOKUP(B25,'[1]Hoja 1'!$A:$J,10,0) -> #REF! | M25: =L25=K25 -> #REF! | N25: =VLOOKUP(B25,'[1]Hoja 1'!$A:$F,6,0) -> #REF!
A26: Claudina del Carmen Campos Castro | B26: 11147079-0 | C26: 5000 | I26: 2000 | K26: SINDICATO INTEREMPRESA SINTRAPAE RENQUI | L26: =VLOOKUP(B26,'[1]Hoja 1'!$A:$J,10,0) -> #REF! | M26: =L26=K26 -> #REF! | N26: =VLOOKUP(B26,'[1]Hoja 1'!$A:$F,6,0) -> #REF!
A27: Bernardita de las Mercedes Salas Sepulveda | B27: 10497251-9 | C27: 5000 | I27: 2000 | K27: SINDICATO INTEREMPRESA SINTRAPAE RENQUI | L27: =VLOOKUP(B27,'[1]Hoja 1'!$A:$J,10,0) -> #REF! | M27: =L27=K27 -> #REF! | N27: =VLOOKUP(B27,'[1]Hoja 1'!$A:$F,6,0) -> #REF!
A28: Viviana Alejandra Salazar Muñoz | B28: 12655315-3 | C28: 5000 | I28: 2000 | K28: SINDICATO INTEREMPRESA SINTRAPAE RENQUI | L28: =VLOOKUP(B28,'[1]Hoja 1'!$A:$J,10,0) -> #REF! | M28: =L28=K28 -> #REF! | N28: =VLOOKUP(B28,'[1]Hoja 1'!$A:$F,6,0) -> #REF!
A29: Evelyn Margarita Soto Elgueta | B29: 16924326-3 | C29: 5000 | I29: 2000 | K29: SINDICATO INTEREMPRESA SINTRAPAE RENQUI | L29: =VLOOKUP(B29,'[1]Hoja 1'!$A:$J,10,0) -> #REF! | M29: =L29=K29 -> #REF! | N29: =VLOOKUP(B29,'[1]Hoja 1'!$A:$F,6,0) -> #REF!
A30: Elizabeth Del Carmen Agurto Soto | B30: 10940546-9 | C30: 5000 | I30: 2000 | K30: SINDICATO INTEREMPRESA SINTRAPAE RENQUI | L30: =VLOOKUP(B30,'[1]Hoja 1'!$A:$J,10,0) -> #REF! | M30: =L30=K30 -> #REF! | N30: =VLOOKUP(B30,'[1]Hoja 1'!$A:$F,6,0) -> #REF!
... A78: Lucero Nicole Hermosilla Ayala | B78: 18329507-1 | C78: 5000 | I78: 2000 | K78: SINDICATO INTEREMPRESA SINTRAPAE RENQUI | L78: =VLOOKUP(B78,'[1]Hoja 1'!$A:$J,10,0) -> #REF! | M78: =L78=K78 -> #REF! | N78: =VLOOKUP(B78,'[1]Hoja 1'!$A:$F,6,0) -> #REF!
A79: Leticia del Pilar Vidal Antipil | B79: 12899642-7 | C79: 2500 | I79: 2000 | J79: DOBLE CUOTA | K79: SINDICATO INTEREMPRESA SINTRAPAE RENQUI | L79: =VLOOKUP(B79,'[1]Hoja 1'!$A:$J,10,0) -> #REF! | M79: =L79=K79 -> #REF! | N79: =VLOOKUP(B79,'[1]Hoja 1'!$A:$F,6,0) -> #REF!
A80: Sandra del Carmen Otárola Acevedo | B80: 13662267-6 | C80: 5000 | I80: 2000 | K80: SINDICATO INTEREMPRESA SINTRAPAE RENQUI | L80: =VLOOKUP(B80,'[1]Hoja 1'!$A:$J,10,0) -> #REF! | M80: =L80=K80 -> #REF! | N80: =VLOOKUP(B80,'[1]Hoja 1'!$A:$F,6,0) -> #REF!
A81: Tamara Andrea Cristy Pradel | B81: 18279265-9 | C81: 5000 | I81: 0 | K81: SINDICATO INTEREMPRESA SINTRAPAE RENQUI | L81: =VLOOKUP(B81,'[1]Hoja 1'!$A:$J,10,0) -> #REF! | M81: =L81=K81 -> #REF! | N81: =VLOOKUP(B81,'[1]Hoja 1'!$A:$F,6,0) -> #REF!
A82: Génesis Griselda Almarza González | B82: 19586396-2 | C82: 5000 | I82: 2000 | K82: SINDICATO INTEREMPRESA SINTRAPAE RENQUI | L82: =VLOOKUP(B82,'[1]Hoja 1'!$A:$J,10,0) -> #REF! | M82: =L82=K82 -> #REF! | N82: =VLOOKUP(B82,'[1]Hoja 1'!$A:$F,6,0) -> #REF!
A83: Margarita de las Mercedes Reyes Rosales | B83: 10289653-K | C83: 5000 | I83: 2000 | K83: SINDICATO INTEREMPRESA SINTRAPAE RENQUI | L83: =VLOOKUP(B83,'[1]Hoja 1'!$A:$J,10,0) -> #REF! | M83: =L83=K83 -> #REF! | N83: =VLOOKUP(B83,'[1]Hoja 1'!$A:$F,6,0) -> #REF!
A84: Olga Maria Álvarez del Río | B84: 11644563-8 | C84: 5000 | I84: 2000 | K84: SINDICATO INTEREMPRESA SINTRAPAE RENQUI | L84: =VLOOKUP(B84,'[1]Hoja 1'!$A:$J,10,0) -> #REF! | M84: =L84=K84 -> #REF! | N84: =VLOOKUP(B84,'[1]Hoja 1'!$A:$F,6,0) -> #REF!
A85: Rosa Viviana Carrasco Bahamondes | B85: 14039893-4 | C85: 5000 | I85: 2000 | K85: SINDICATO INTEREMPRESA SINTRAPAE RENQUI | L85: =VLOOKUP(B85,'[1]Hoja 1'!$A:$J,10,0) -> #REF! | M85: =L85=K85 -> #REF! | N85: =VLOOKUP(B85,'[1]Hoja 1'!$A:$F,6,0) -> #REF!
A86: Elizabeth Catherine Palacios Negrete | B86: 13036778-K | C86: 5000 | I86: 2000 | K86: SINDICATO INTEREMPRESA SINTRAPAE RENQUI | L86: =VLOOKUP(B86,'[1]Hoja 1'!$A:$J,10,0) -> #REF! | M86: =L86=K86 -> #REF! | N86: =VLOOKUP(B86,'[1]Hoja 1'!$A:$F,6,0) -> #REF!
A87: Isolina de las Mercedes González González | B87: 13085735-3 | C87: 5000 | I87: 2000 | K87: SINDICATO INTEREMPRESA SINTRAPAE RENQUI | L87: =VLOOKUP(B87,'[1]Hoja 1'!$A:$J,10,0) -> #REF! | M87: =L87=K87 -> #REF! | N87: =VLOOKUP(B87,'[1]Hoja 1'!$A:$F,6,0) -> #REF!
A88: Fernanda Tabita Melillan Garrido | B88: 19678087-4 | C88: 5000 | I88: 2000 | K88: SINDICATO INTEREMPRESA SINTRAPAE RENQUI | L88: =VLOOKUP(B88,'[1]Hoja 1'!$A:$J,10,0) -> #REF! | M88: =L88=K88 -> #REF! | N88: =VLOOKUP(B88,'[1]Hoja 1'!$A:$F,6,0) -> #REF!
A89: Estefanía Magaly Gallardo Rojas | B89: 16787712-5 | C89: 5000 | I89: 2000 | K89: SINDICATO INTEREMPRESA SINTRAPAE RENQUI | L89: =VLOOKUP(B89,'[1]Hoja 1'!$A:$J,10,0) -> #REF! | M89: =L89=K89 -> #REF! | N89: =VLOOKUP(B89,'[1]Hoja 1'!$A:$F,6,0) -> #REF!
...

Sheet CORRECIONES
A2: NOMBRE | B2: RUT | C2: motivo | D2: corregir | E2: SINDICATO
A3: VEJAR PINO PAMELA ALEJANDRA | B3: 16692656-7 | C3: ERROR EN EN EL RUT | D3: 16692646-7 | E3: SINDICATO INTEREMPRESA ALISERVICE DISTAL
A4: PAVEZ PRADENAS | B4: 22584903-K | C4: FINIQUITADA | E4: SINDICATO INTEREMPRESA ALISERVICE DISTAL
A5: GALLARDO MERY NICOL | B5: 18636141-1 | C5: ERROR EN EN EL RUT | D5: 18363141-1 | E5: SINDICATO INTEREMPRESA MANIPULADORAS GUERRERA PAE
A6: PAINE NIETO MARGARITA | B6: 9410734-2 | C6: FINIQUITADA | E6: SINDICATO INTEREMPRESA MANIPULADORAS GUERRERA PAE
A7: CAMILA MAKARENA CHAVEZ CHAVEZ | B7: 19095775-9 | C7: ERROR EN EN EL RUT | D7: 19095775-6 | E7: SINDICATO INTEREMPRESA MUJERES INDEPENDIENTES

Sheet SINDICATOS RECIBIDOS
A1: SINDICATO | B1: RECIBIDOS
A2: SINDICATO INTEREMPRESA MANIPULADORAS PAE SIMPAE | B2: si
A3: SINDICATO NACIONAL INTEREMPRESA MANIPULADORA DE ALIMENTOS
A4: SINDICATO QUINTA NORMAL
A5: SINDICATO INTEREMPRESA MANIPULADORAS GUERRERA PAE | B5: si
A6: SINDICATO INTEREMPRESA MUJERES INDEPENDIENTES | B6: si
A7: SINDICATO INTEREMPRESA SINTRAPAE RENQUI | B7: si
A8: SINDICATO INTEREMPRESA DE MANIPULADORAS DE ALIMENTOS LO PRADO | B8: si
A9: SINDICATO INTEREMPRESA SANTIAGO UNIDO | B9: si
A10: SINDICATO INTEREMPRESA ALISERVICE DISTAL | B10: si
A11: SINDICATO INTEREMPRESA DE MANIPULADORAS DE ALIMENTOS DE LA PROVINCIA CORDILLERA | B11: si
A12: SINDICATO SME (2026)
A13: SINDICATO INTEREMPRESA MANIPULADORAS DE ALIMENTO PAE Y PAP (LO BARNECHEA)
A14: SINDICATO INTEREMPRESA DE MANIPULADORAS DE ALIMENTOS SANTIAGO SUR N1
A15: SINDICATO INTEREMPRESA MANIPULADORAS PAE PAP
A16: SITAL | B16: si

Sheet REX+
A1: Plantilla | B1: Nombre colaborador | C1: Contrato | D1: Nombre de contrato | E1: cuotasindical | F1: sindsimpaecuotaconfp | G1: descuentodental | H1: descplantelefonico | I1: multasindical | J1: otrosdescuentossind | K1: cuotasindical2 | L1: Oservacion
A2: 11971775-2 | B2: NANCY MADARIAGA | C2: =VLOOKUP(A2,'Hoja 2'!A:C,3,0) -> 1 | D2: =VLOOKUP(A2,'Hoja 2'!A:D,4,0) -> Contrato 1 | E2: 0 | F2: 0 | G2: 0 | H2: 0 | I2: 0 | J2: 0 | K2: 5000 | L2: DOBLE CUOTA
A3: 18122103-8 | B3: GLADYS POBLETE | C3: =VLOOKUP(A3,'Hoja 2'!A:C,3,0) -> 1 | D3: =VLOOKUP(A3,'Hoja 2'!A:D,4,0) -> Contrato 1 | E3: 0 | F3: 0 | G3: 0 | H3: 0 | I3: 0 | J3: 0 | K3: 5000 | L3: DOBLE CUOTA
A4: 12406831-2 | B4: GIOCONDA RETAMALES | C4: =VLOOKUP(A4,'Hoja 2'!A:C,3,0) -> 1 | D4: =VLOOKUP(A4,'Hoja 2'!A:D,4,0) -> Contrato 1 | E4: 0 | F4: 0 | G4: 0 | H4: 0 | I4: 0 | J4: 0 | K4: 5000 | L4: DOBLE CUOTA
A5: 13031543-7 | B5: EDITH BORDILLO | C5: =VLOOKUP(A5,'Hoja 2'!A:C,3,0) -> 1 | D5: =VLOOKUP(A5,'Hoja 2'!A:D,4,0) -> Contrato 1 | E5: 0 | F5: 0 | G5: 0 | H5: 0 | I5: 0 | J5: 0 | K5: 5000 | L5: DOBLE CUOTA
A6: 11293958-K | B6: AURORA ELOISA CARRASCO ALARCON | C6: =VLOOKUP(A6,'Hoja 2'!A:C,3,0) -> 1 | D6: =VLOOKUP(A6,'Hoja 2'!A:D,4,0) -> Contrato 1 | E6: 0 | F6: 0 | G6: 0 | H6: 0 | I6: 0 | J6: 0 | K6: 5000 | L6: DOBLE CUOTA
A7: 20139231-4 | B7: CAROLINA ALEXANDRA VASQUEZ GOMEZ | C7: =VLOOKUP(A7,'Hoja 2'!A:C,3,0) -> 1 | D7: =VLOOKUP(A7,'Hoja 2'!A:D,4,0) -> Contrato 1 | E7: 0 | F7: 0 | G7: 0 | H7: 0 | I7: 0 | J7: 0 | K7: 5000 | L7: DOBLE CUOTA
A8: 9479341-6 | B8: CORINA DEL CARMEN GONZALEZ MUÑOZ | C8: =VLOOKUP(A8,'Hoja 2'!A:C,3,0) -> 1 | D8: =VLOOKUP(A8,'Hoja 2'!A:D,4,0) -> Contrato 1 | E8: 0 | F8: 0 | G8: 0 | H8: 0 | I8: 0 | J8: 0 | K8: 5000 | L8: DOBLE CUOTA
A9: 8603844-7 | B9: ELSA CLARA BERGUÑO SANTIBAÑEZ | C9: =VLOOKUP(A9,'Hoja 2'!A:C,3,0) -> 1 | D9: =VLOOKUP(A9,'Hoja 2'!A:D,4,0) -> Contrato 1 | E9: 0 | F9: 0 | G9: 0 | H9: 0 | I9: 0 | J9: 0 | K9: 5000 | L9: DOBLE CUOTA
A10: 12906922-8 | B10: JESSICA SOLANGE VARGAS BELLO | C10: =VLOOKUP(A10,'Hoja 2'!A:C,3,0) -> 1 | D10: =VLOOKUP(A10,'Hoja 2'!A:D,4,0) -> Contrato 1 | E10: 0 | F10: 0 | G10: 0 | H10: 0 | I10: 0 | J10: 0 | K10: 5000 | L10: DOBLE CUOTA
A11: 16932964-8 | B11: KATHERINE BEATRIZ CARMONA GONZALEZ | C11: =VLOOKUP(A11,'Hoja 2'!A:C,3,0) -> 1 | D11: =VLOOKUP(A11,'Hoja 2'!A:D,4,0) -> Contrato 1 | E11: 0 | F11: 0 | G11: 0 | H11: 0 | I11: 0 | J11: 0 | K11: 5000 | L11: DOBLE CUOTA
A12: 15587846-0 | B12: KATHERIN YSABEL GOMEZ NUÑEZ | C12: =VLOOKUP(A12,'Hoja 2'!A:C,3,0) -> 1 | D12: =VLOOKUP(A12,'Hoja 2'!A:D,4,0) -> Contrato 1 | E12: 0 | F12: 0 | G12: 0 | H12: 0 | I12: 0 | J12: 0 | K12: 5000 | L12: DOBLE CUOTA
A13: 11796214-8 | B13: LUZ JIMENA TRAGO ANTIMAN | C13: =VLOOKUP(A13,'Hoja 2'!A:C,3,0) -> 1 | D13: =VLOOKUP(A13,'Hoja 2'!A:D,4,0) -> Contrato 1 | E13: 0 | F13: 0 | G13: 0 | H13: 0 | I13: 0 | J13: 0 | K13: 5000 | L13: DOBLE CUOTA
... A16: 12397855-2 | B16: SUSSY MAGALY TAPIA PEREZ | C16: =VLOOKUP(A16,'Hoja 2'!A:C,3,0) -> 1 | D16: =VLOOKUP(A16,'Hoja 2'!A:D,4,0) -> Contrato 1 | E16: 0 | F16: 0 | G16: 0 | H16: 0 | I16: 0 | J16: 0 | K16: 5000 | L16: DOBLE CUOTA
A17: 12875395-8 | B17: FANNY DEL CARMEN RAMUREZ JARA | C17: =VLOOKUP(A17,'Hoja 2'!A:C,3,0) -> 1 | D17: =VLOOKUP(A17,'Hoja 2'!A:D,4,0) -> Contrato 1 | E17: 0 | F17: 0 | G17: 0 | H17: 0 | I17: 0 | J17: 0 | K17: 0
A18: 13835916-6 | B18: LYNDA RAQUEL ARAGON VALDES | C18: =VLOOKUP(A18,'Hoja 2'!A:C,3,0) -> 1 | D18: =VLOOKUP(A18,'Hoja 2'!A:D,4,0) -> Contrato 1 | E18: 0 | F18: 0 | G18: 0 | H18: 0 | I18: 0 | J18: 0 | K18: 0
A19: 10459663-0 | B19: María Jacqueline Bazan Orellana | C19: =VLOOKUP(A19,'Hoja 2'!A:C,3,0) -> 1 | D19: =VLOOKUP(A19,'Hoja 2'!A:D,4,0) -> Contrato 1 | E19: 0 | F19: 0 | G19: 0 | H19: 0 | I19: 0 | J19: 2000 | K19: 0
A20: 11549620-4 | B20: Elena Margarita Ayala Cabrera | C20: =VLOOKUP(A20,'Hoja 2'!A:C,3,0) -> 1 | D20: =VLOOKUP(A20,'Hoja 2'!A:D,4,0) -> Contrato 1 | E20: 0 | F20: 0 | G20: 0 | H20: 0 | I20: 0 | J20: 2000 | K20: 0
A21: 10471922-8 | B21: Elsa Marisol Llanca Saavedra | C21: =VLOOKUP(A21,'Hoja 2'!A:C,3,0) -> 1 | D21: =VLOOKUP(A21,'Hoja 2'!A:D,4,0) -> Contrato 1 | E21: 0 | F21: 0 | G21: 0 | H21: 0 | I21: 0 | J21: 2000 | K21: 0
A22: 15481206-7 | B22: Yocelyn del Carmen Zapata Yáñez | C22: =VLOOKUP(A22,'Hoja 2'!A:C,3,0) -> 1 | D22: =VLOOKUP(A22,'Hoja 2'!A:D,4,0) -> Contrato Manipuladora | E22: 0 | F22: 0 | G22: 0 | H22: 0 | I22: 0 | J22: 2000 | K22: 0
A23: 10074715-4 | B23: Laura del Carmen Molina Delgado | C23: =VLOOKUP(A23,'Hoja 2'!A:C,3,0) -> 1 | D23: =VLOOKUP(A23,'Hoja 2'!A:D,4,0) -> Contrato 1 | E23: 0 | F23: 0 | G23: 0 | H23: 0 | I23: 0 | J23: 2000 | K23: 0
A24: 15505258-9 | B24: Elizabeth Johana Aburto Silva | C24: =VLOOKUP(A24,'Hoja 2'!A:C,3,0) -> 1 | D24: =VLOOKUP(A24,'Hoja 2'!A:D,4,0) -> Contrato 1 | E24: 0 | F24: 0 | G24: 0 | H24: 0 | I24: 0 | J24: 2000 | K24: 0
A25: 17425935-6 | B25: Mariana Daniela Toledo jaque | C25: =VLOOKUP(A25,'Hoja 2'!A:C,3,0) -> 1 | D25: =VLOOKUP(A25,'Hoja 2'!A:D,4,0) -> Contrato 1 | E25: 0 | F25: 0 | G25: 0 | H25: 0 | I25: 0 | J25: 2000 | K25: 0
A26: 11147079-0 | B26: Claudina del Carmen Campos Castro | C26: =VLOOKUP(A26,'Hoja 2'!A:C,3,0) -> 1 | D26: =VLOOKUP(A26,'Hoja 2'!A:D,4,0) -> Contrato 1 | E26: 0 | F26: 0 | G26: 0 | H26: 0 | I26: 0 | J26: 2000 | K26: 0
A27: 10497251-9 | B27: Bernardita de las Mercedes Salas Sepulveda | C27: =VLOOKUP(A27,'Hoja 2'!A:C,3,0) -> 1 | D27: =VLOOKUP(A27,'Hoja 2'!A:D,4,0) -> Contrato 1 | E27: 0 | F27: 0 | G27: 0 | H27: 0 | I27: 0 | J27: 2000 | K27: 0
A28: 12655315-3 | B28: Viviana Alejandra Salazar Muñoz | C28: =VLOOKUP(A28,'Hoja 2'!A:C,3,0) -> 1 | D28: =VLOOKUP(A28,'Hoja 2'!A:D,4,0) -> Contrato 1 | E28: 0 | F28: 0 | G28: 0 | H28: 0 | I28: 0 | J28: 2000 | K28: 0
... A78: 18329507-1 | B78: Lucero Nicole Hermosilla Ayala | C78: =VLOOKUP(A78,'Hoja 2'!A:C,3,0) -> 1 | D78: =VLOOKUP(A78,'Hoja 2'!A:D,4,0) -> Contrato 1 | E78: 0 | F78: 0 | G78: 0 | H78: 0 | I78: 0 | J78: 2000 | K78: 2500
A79: 12899642-7 | B79: Leticia del Pilar Vidal Antipil | C79: =VLOOKUP(A79,'Hoja 2'!A:C,3,0) -> 1 | D79: =VLOOKUP(A79,'Hoja 2'!A:D,4,0) -> Contrato 1 | E79: 0 | F79: 0 | G79: 0 | H79: 0 | I79: 0 | J79: 2000 | K79: 0 | L79: DOBLE CUOTA
A80: 13662267-6 | B80: Sandra del Carmen Otárola Acevedo | C80: =VLOOKUP(A80,'Hoja 2'!A:C,3,0) -> 1 | D80: =VLOOKUP(A80,'Hoja 2'!A:D,4,0) -> Contrato 1 | E80: 0 | F80: 0 | G80: 0 | H80: 0 | I80: 0 | J80: 0 | K80: 0
A81: 18279265-9 | B81: Tamara Andrea Cristy Pradel | C81: =VLOOKUP(A81,'Hoja 2'!A:C,3,0) -> 1 | D81: =VLOOKUP(A81,'Hoja 2'!A:D,4,0) -> Contrato 1 | E81: 0 | F81: 0 | G81: 0 | H81: 0 | I81: 0 | J81: 2000 | K81: 0
A82: 19586396-2 | B82: Génesis Griselda Almarza González | C82: =VLOOKUP(A82,'Hoja 2'!A:C,3,0) -> 1 | D82: =VLOOKUP(A82,'Hoja 2'!A:D,4,0) -> Contrato 1 | E82: 0 | F82: 0 | G82: 0 | H82: 0 | I82: 0 | J82: 2000 | K82: 0
A83: 10289653-K | B83: Margarita de las Mercedes Reyes Rosales | C83: =VLOOKUP(A83,'Hoja 2'!A:C,3,0) -> 1 | D83: =VLOOKUP(A83,'Hoja 2'!A:D,4,0) -> Contrato 1 | E83: 0 | F83: 0 | G83: 0 | H83: 0 | I83: 0 | J83: 2000 | K83: 0
A84: 11644563-8 | B84: Olga Maria Álvarez del Río | C84: =VLOOKUP(A84,'Hoja 2'!A:C,3,0) -> 1 | D84: =VLOOKUP(A84,'Hoja 2'!A:D,4,0) -> Contrato 1 | E84: 0 | F84: 0 | G84: 0 | H84: 0 | I84: 0 | J84: 2000 | K84: 0
A85: 14039893-4 | B85: Rosa Viviana Carrasco Bahamondes | C85: =VLOOKUP(A85,'Hoja 2'!A:C,3,0) -> 1 | D85: =VLOOKUP(A85,'Hoja 2'!A:D,4,0) -> Contrato 1 | E85: 0 | F85: 0 | G85: 0 | H85: 0 | I85: 0 | J85: 2000 | K85: 0
A86: 13036778-K | B86: Elizabeth Catherine Palacios Negrete | C86: =VLOOKUP(A86,'Hoja 2'!A:C,3,0) -> 1 | D86: =VLOOKUP(A86,'Hoja 2'!A:D,4,0) -> Contrato 1 | E86: 0 | F86: 0 | G86: 0 | H86: 0 | I86: 0 | J86: 2000 | K86: 0
A87: 13085735-3 | B87: Isolina de las Mercedes González González | C87: =VLOOKUP(A87,'Hoja 2'!A:C,3,0) -> 1 | D87: =VLOOKUP(A87,'Hoja 2'!A:D,4,0) -> Contrato 1 | E87: 0 | F87: 0 | G87: 0 | H87: 0 | I87: 0 | J87: 2000 | K87: 0
A88: 19678087-4 | B88: Fernanda Tabita Melillan Garrido | C88: =VLOOKUP(A88,'Hoja 2'!A:C,3,0) -> 2 | D88: =VLOOKUP(A88,'Hoja 2'!A:D,4,0) -> Contrato 2 | E88: 0 | F88: 0 | G88: 0 | H88: 0 | I88: 0 | J88: 2000 | K88: 0
A89: 16787712-5 | B89: Estefanía Magaly Gallardo Rojas | C89: =VLOOKUP(A89,'Hoja 2'!A:C,3,0) -> 2 | D89: =VLOOKUP(A89,'Hoja 2'!A:D,4,0) -> Contrato 2 | E89: 0 | F89: 0 | G89: 0 | H89: 0 | I89: 0 | J89: 2000 | K89: 0
A90: 12672756-9 | B90: Monica del Carmen Borquez Borquez | C90: =VLOOKUP(A90,'Hoja 2'!A:C,3,0) -> 1 | D90: =VLOOKUP(A90,'Hoja 2'!A:D,4,0) -> CONTRATO 1 | E90: 0 | F90: 0 | G90: 0 | H90: 0 | I90: 0 | J90: 2000 | K90: 0
A91: 10549585-4 | B91: Soledad Ivonne Gutierrez Valdivia | C91: =VLOOKUP(A91,'Hoja 2'!A:C,3,0) -> 1 | D91: =VLOOKUP(A91,'Hoja 2'!A:D,4,0) -> Contrato 1 | E91: 0 | F91: 0 | G91: 0 | H91: 0 | I91: 0 | J91: 2000 | K91: 0
...

Sheet Hoja 2
A1: Plantilla | B1: Nombre colaborador | C1: Contrato | D1: Nombre de contrato
A2: 10011747-9 | B2: FIGUEROA ARANDA VERONICA DEL CARMEN | C2: 1 | D2: Contrato 1
A3: 10024007-6 | B3: CRUZ GUTIERREZ GRICELDA ANGELICA | C3: 1 | D3: Contrato 1
A4: 10047557-K | B4: HERMOSILLA REYES LIDIA DEL CARMEN | C4: 1 | D4: Contrato 1
A5: 10074715-4 | B5: MOLINA DELGADO LAURA DEL CARMEN | C5: 1 | D5: Contrato 1
A6: 10081913-9 | B6: MARTINEZ VALENZUELA ESTRELLA DEL CARMEN | C6: 1 | D6: Contrato 1
A7: 10115215-4 | B7: AREVALO VILLARROEL NANCY EUGENIA | C7: 1 | D7: Contrato 1
A8: 10143653-5 | B8: BRICEÑO ROMERO SILVIA DEL CARMEN | C8: 1 | D8: Contrato 1
A9: 10147004-0 | B9: VASQUEZ TENO MARISOL DE LAS MERCEDES | C9: 1 | D9: Contrato 1
A10: 10194223-6 | B10: RABANAL RAMOS CLAUDIA MONICA | C10: 1 | D10: Contrato 1
A11: 10197877-K | B11: MUÑOZ GAJARDO ROSA MARITZA | C11: 1 | D11: Contrato 1
A12: 10224404-4 | B12: VARELA ARAVENA ADRIANA IVON | C12: 1 | D12: Contrato 1
A13: 10250776-2 | B13: LOBOS RUBIO IRENE DEL CARMEN | C13: 1 | D13: Contrato 1
... A847: 9991284-7 | B847: TRONCOSO RODRIGUEZ ANA MARIA | C847: 1 | D847: Contrato 1
